Workbook

Sheet Matriz
A1: Trasteando — Matriz de cumplimiento de requisitos
A2: Base: requisitos.md v1.2 · app 0.1.2 · roadmap 3.0 · emitida el 14/10/2026. Cliente: Pablo Díaz Guerra. Proveedor: chat de Desarrollo. Verificación independiente: auditores de requisitos y técnico.
A4: ID | B4: Categoría | C4: Requisito | D4: Prioridad | E4: Origen | F4: Fase | G4: Etapa | H4: Método | I4: Criterio de aceptación | J4: Declaración del proveedor | K4: Desde versión | L4: Evidencia | M4: Estado de verificación | N4: Verifica | O4: Comentario del proveedor | P4: Comentario del cliente | Q4: Cambio en v1.2
A5: G-01 | B5: Requisitos generales y de producto | C5: La aplicación se llama Trasteando. El nombre aparece en la pantalla de entrada, el título de la pestaña y el manifiesto PWA. | D5: Alta | E5: Cliente · listado 14/09 | F5: F1 | G5: F1.1 | H5: I | I5: El nombre «Trasteando» aparece en la pantalla de entrada, en la pestaña del navegador y en el manifiesto. | J5: Cumple | K5: 0.1.0 | L5: F1.1 #14 | M5: Pendiente | N5: Auditor de requisitos | O5: Naming cerrado: se descarta Trasting.
A6: G-02 | B6: Requisitos generales y de producto | C6: La app se organiza en áreas accesibles desde una navegación principal: Libre, Adivinar, Afinador y Escalas. | D6: Alta | E6: Cliente · listado 14/09 | F6: F1 | G6: F1.1 | H6: D | I6: La barra inferior muestra Libre, Adivinar, Afinador y Escalas; cada destino activo abre su vista y Escalas aparece deshabilitada. | J6: Cumple | K6: 0.1.0 | L6: F1.1 #1 y #14 | M6: Pendiente | N6: Cliente | O6: Escalas visible pero deshabilitada hasta F5.
A7: G-03 | B7: Requisitos generales y de producto | C7: La app funciona sin conexión una vez cargada desde la web. | D7: Media | E7: Cliente · listado 14/09 | F7: F6 | G7: F6.2 | H7: T | I7: Tras una primera carga desde la web y con el modo avión activado, la app abre y suena. | J7: No cumple | K7: — | L7: — | M7: Pendiente | N7: Banco automático + auditor técnico | O7: Service Worker. Depende de S-07. En modo archivo (G-07) la autonomía se consigue de otra forma: el audio va dentro del archivo. | Q7: Modificado
A8: G-04 | B8: Requisitos generales y de producto | C8: La app es instalable como PWA (icono en la pantalla de inicio, pantalla completa). | D8: Alta | E8: Cliente · listado 14/09 | F8: F6 · F7 | G8: F6.3 · F7.2 | H8: D | I8: Desde la web publicada, el navegador ofrece instalarla y abre a pantalla completa desde el icono. | J8: Cumple parcialmente | K8: 0.1.0 | L8: — | M8: Pendiente | N8: Cliente | O8: Manifiesto incrustado como data: URL. Falta un archivo de manifiesto propio con iconos PNG (F6.3) y verificarla instalada desde la web publicada (F7.2): instalar solo es posible desde https. | Q8: Modificado
A9: G-05 | B9: Requisitos generales y de producto | C9: La interfaz cumple unos mínimos de accesibilidad: foco de teclado visible, respeto a prefers-reduced-motion, contraste suficiente y etiquetas accesibles en los controles solo-icono. | D9: Media | E9: Desarrollo · v1.1 | F9: F3 | G9: F3.4 | H9: I+T | I9: Todo control es alcanzable con teclado y muestra el foco; contrastes ≥ 4,5:1 medidos; el movimiento se reduce con prefers-reduced-motion. | J9: Cumple parcialmente | K9: 0.1.1 | L9: — | M9: Pendiente | N9: Auditor técnico | O9: Hecho: foco visible, movimiento reducido, interruptores con role="switch" (0.1.1), aria-pressed en los selectores y aviso del reto para lectores de pantalla (0.1.2). Falta: recorrer el mástil con teclado y auditar el contraste. | Q9: Modificado
A10: G-06 | B10: Requisitos generales y de producto | C10: El proyecto documenta sus dependencias externas y la licencia de cada recurso de terceros que distribuye. | D10: Media | E10: Desarrollo · v1.1 | F10: F2 · F6 | G10: F2.1 · F6.4 | H10: I | I10: CREDITOS.md lista cada recurso de terceros con su origen y su licencia. | J10: No cumple | K10: — | L10: — | M10: Pendiente | N10: Auditor de requisitos | O10: Tone.js (MIT) y los samples de audio (S-07).
A11: G-07 | B11: Requisitos generales y de producto | C11: Modo archivo autónomo: la app funciona completa —salvo el afinador por micrófono— abriendo el archivo directamente (file://), sin servidor y sin conexión. | D11: Alta | E11: Cliente · 15/09 | F11: F2 | G11: F2.3 · F2.5 | H11: T | I11: Con el ordenador en modo avión, abrir el archivo con doble clic: suenan las muestras reales y funcionan Libre, Adivinar y el afinador por referencia. | J11: Cumple parcialmente | K11: 0.1.0 | L11: — | M11: Pendiente | N11: Banco automático + auditor técnico | O11: Hoy funciona sin conexión pero con sonido sintetizado, porque los samples se descargan de internet. Se completa al incrustar el audio en el archivo (F2.3). En iPhone puede no ser viable: ver PL-03. | Q11: Nuevo
A12: G-08 | B12: Requisitos generales y de producto | C12: El proyecto conserva dos formas de distribución equivalentes: el archivo autónomo (para llevárselo) y la web publicada (para instalarla como PWA). | D12: Media | E12: Cliente · 15/09 | F12: F4 · F6 | G12: F4.1 · F6.1 | H12: T | I12: El archivo autónomo generado y la web publicada superan el mismo banco de pruebas. | J12: Cumple parcialmente | K12: 0.1.0 | L12: — | M12: Pendiente | N12: Banco automático + auditor técnico | O12: Hoy se cumple de forma trivial: todo es un único archivo. Se vuelve exigente al pasar a módulos (F4.1), que no funcionan con file://; F6.1 genera el archivo autónomo a partir de ellos. | Q12: Nuevo
A13: G-09 | B13: Requisitos generales y de producto | C13: La app podrá distribuirse por tiendas oficiales —Google Play, Microsoft Store y, si compensa, App Store— empaquetando la PWA publicada. | D13: Media | E13: Cliente · 14/10 | F13: F7 | G13: F7.4 | H13: I | I13: Ficha enviada a revisión en al menos una tienda, o decisión documentada de no hacerlo. | J13: No cumple | K13: — | L13: — | M13: Pendiente | N13: Auditor de requisitos | O13: Decisión de producto en F7.4. Exige S-07 con licencia limpia, G-11 y la web publicada (X-02). Cuentas, costes y archivos necesarios: roadmap, Inventario de lanzamiento. | Q13: Nuevo
A14: G-10 | B14: Requisitos generales y de producto | C14: Control de versiones de la app: cada versión tiene número propio con la pauta 0.‹fase›.‹corrección› —1.0.0 en el lanzamiento—, se registra en CHANGELOG.md y se muestra en Ajustes. | D14: Alta | E14: Cliente · 14/10 | F14: F1 | G14: F1.3 | H14: I | I14: Ajustes muestra la versión; CHANGELOG.md tiene una entrada por versión; existe la etiqueta de Git de cada cierre de fase. | J14: Cumple | K14: 0.1.2 | L14: Banco 0.1.2 (DOM simulado) · CHANGELOG.md · F1.1 #12 | M14: Verificado parcialmente | N14: Auditor de requisitos | O14: Vincula cada versión con su fase del roadmap. Cada fase cerrada se marca además con una etiqueta de Git (F1.4). | Q14: Nuevo
A15: G-11 | B15: Requisitos generales y de producto | C15: Privacidad: la app no recoge ni envía datos personales; el sonido del micrófono se analiza solo en el dispositivo. Una política de privacidad pública lo declara. | D15: Alta | E15: Desarrollo · v1.2 | F15: F6 | G15: F6.4 | H15: I | I15: La política de privacidad está publicada y la app no envía ninguna petición con datos del usuario (pestaña Red). | J15: No cumple | K15: — | L15: — | M15: Pendiente | N15: Auditor de requisitos | O15: Las tiendas exigen política de privacidad, y el micrófono la hace necesaria también por transparencia. Hoy la app ya no envía nada: solo guarda ajustes en el propio navegador. | Q15: Nuevo
A16: PL-01 | B16: Plataformas | C16: Windows: la app funciona en Chrome, Edge y Firefox actuales —en modo archivo, local y web— e instalada como PWA desde Edge o Chrome. | D16: Alta | E16: Cliente · 14/10 | F16: F2 · F7 | G16: F2.5 · F7.2 | H16: D | I16: La lista de F1.1 se supera en Chrome, Edge y Firefox en Windows, y la app se instala como PWA desde Edge. | J16: Cumple parcialmente | K16: 0.1.0 | L16: — | M16: Pendiente | N16: Cliente | O16: Es la plataforma de desarrollo y la mejor cubierta. Tienda: Microsoft Store (F7.4). | Q16: Nuevo
A17: PL-02 | B17: Plataformas | C17: Android: la app funciona en Chrome —en web e instalada como PWA— y, si es viable, en modo archivo. | D17: Alta | E17: Cliente · 14/10 | F17: F2 · F7 | G17: F2.5 · F7.2 | H17: D | I17: La lista de comprobación se supera en Chrome para Android, en web y con la PWA instalada. | J17: Cumple parcialmente | K17: 0.1.0 | L17: — | M17: Pendiente | N17: Cliente | O17: Modo archivo: abrir el HTML descargado con Chrome; a verificar en F2.5. Tienda: Google Play empaquetando la PWA (F7.4). | Q17: Nuevo
A18: PL-03 | B18: Plataformas | C18: iPhone y iPad: la app funciona en Safari —en web e instalada con «Añadir a pantalla de inicio». | D18: Alta | E18: Cliente · 14/10 | F18: F2 · F7 | G18: F2.5 · F7.2 | H18: D | I18: La lista de comprobación se supera en Safari para iOS, en web y desde la pantalla de inicio. | J18: Cumple parcialmente | K18: 0.1.0 | L18: — | M18: Pendiente | N18: Cliente | O18: Modo archivo probablemente inviable: la vista previa de la app Archivos no ejecuta JavaScript (a confirmar en F2.5). Alternativas: el navegador integrado de una app de terceros o un despliegue de pruebas. Tienda: App Store exige un Mac con Xcode y la cuenta de desarrollador de Apple (F7.4). | Q18: Nuevo
A19: N-01 | B19: Nomenclatura y notación | C19: Alternancia entre nomenclatura latina (Do, Re, Mi…) y anglosajona (C, D, E…). | D19: Alta | E19: Cliente · listado 14/09 | F19: F1 | G19: F1.1 | H19: D | I19: El chip de nomenclatura alterna todos los nombres entre Do-Re-Mi y C-D-E. | J19: Cumple | K19: 0.1.0 | L19: F1.1 #6 | M19: Pendiente | N19: Cliente
A20: N-02 | B20: Nomenclatura y notación | C20: El cambio de nomenclatura está en el menú de configuración. | D20: Alta | E20: Cliente · listado 14/09 | F20: F1 | G20: F1.1 | H20: D | I20: El selector de Ajustes produce el mismo cambio que el chip. | J20: Cumple | K20: 0.1.0 | L20: F1.1 #14 | M20: Pendiente | N20: Cliente
A21: N-03 | B21: Nomenclatura y notación | C21: El cambio de nomenclatura está además en la interfaz principal, sin abrir el menú. | D21: Alta | E21: Cliente · listado 14/09 | F21: F1 | G21: F1.1 | H21: D | I21: El chip está visible en la barra de acceso rápido sin abrir ningún menú. | J21: Cumple | K21: 0.1.0 | L21: F1.1 #14 | M21: Pendiente | N21: Cliente | O21: Chip en la barra de acceso rápido.
A22: N-04 | B22: Nomenclatura y notación | C22: La nomenclatura se aplica de forma consistente en mástil, juego, afinador y pentagrama. | D22: Alta | E22: Cliente · listado 14/09 | F22: F1 | G22: F1.1 | H22: D | I22: Tras cambiar la nomenclatura, mástil, cuerdas, lector de nota, pistas y afinador usan la nueva. | J22: Cumple | K22: 0.1.0 | L22: F1.1 #6 | M22: Pendiente | N22: Cliente | O22: Verificar de nuevo al añadir Escalas (F5).
A23: N-05 | B23: Nomenclatura y notación | C23: La nomenclatura persiste entre sesiones. | D23: Media | E23: Cliente · listado 14/09 | F23: F1 | G23: F1.1 | H23: D | I23: Tras recargar la página se mantiene la nomenclatura elegida. | J23: Cumple | K23: 0.1.0 | L23: F1.1 #13 | M23: Pendiente | N23: Cliente | O23: localStorage.
A24: D-01 | B24: Diapasón | C24: Diagrama del mástil de 6 cuerdas. | D24: Alta | E24: Cliente · listado 14/09 | F24: F1 | G24: F1.1 | H24: I | I24: Se dibujan 6 cuerdas con 25 posiciones cada una: cejuela y 24 trastes. | J24: Cumple | K24: 0.1.0 | L24: Banco 0.1.2 (DOM simulado): 150 celdas | M24: Verificado parcialmente | N24: Auditor de requisitos
A25: D-02 | B25: Diapasón | C25: Cada cuerda muestra a la izquierda su nota al aire, derivada de la afinación activa. | D25: Alta | E25: Cliente · listado 14/09 | F25: F1 | G25: F1.1 | H25: D | I25: La etiqueta de cada cuerda coincide con la afinación activa y cambia al cambiarla. | J25: Cumple | K25: 0.1.0 | L25: Banco 0.1.2 (DOM simulado): Drop D | M25: Verificado parcialmente | N25: Cliente | O25: Se actualiza sola al cambiar de afinación (A-10).
A26: D-03 | B26: Diapasón | C26: Cada traste muestra su número alineado exactamente sobre la franja donde se pulsa. | D26: Alta | E26: Cliente · listado 14/09 | F26: F1 | G26: F1.1 | H26: I | I26: Cada número de traste queda centrado sobre su franja con cualquier nivel de zoom. | J26: Cumple | K26: 0.1.0 | L26: F1.1 #7 | M26: Pendiente | N26: Auditor de requisitos | O26: La fila de números comparte las mismas variables de ancho (--label-w, --nut-w, --fret-w) que las celdas.
A27: D-04 | B27: Diapasón | C27: La numeración de trastes tiene tres modos: todos, guía (solo los trastes con marca) y ninguno. | D27: Media | E27: Cliente · listado 14/09 | F27: F1 | G27: F1.3 | H27: T | I27: Los modos Todos, Guía y No muestran todos los números, solo los de trastes con marca, o ninguno. | J27: Cumple | K27: 0.1.2 | L27: Banco 0.1.2 (DOM simulado) · F1.1 #11 | M27: Verificado parcialmente | N27: Banco automático + auditor técnico | O27: Sustituye al interruptor de la 0.1.1; quien lo tuviera apagado pasa automáticamente a «ninguno». | Q27: Modificado
A28: D-05 | B28: Diapasón | C28: Al pulsar una posición suena esa nota. | D28: Alta | E28: Cliente · listado 14/09 | F28: F1 | G28: F1.1 | H28: D | I28: Pulsar una posición reproduce su nota sin retardo perceptible. | J28: Cumple | K28: 0.1.0 | L28: F1.1 #2 | M28: Pendiente | N28: Cliente
A29: D-06 | B29: Diapasón | C29: Al pulsar una posición aparece el nombre de la nota en la nomenclatura activa. | D29: Alta | E29: Cliente · listado 14/09 | F29: F1 | G29: F1.1 | H29: D | I29: Al pulsar aparece el nombre de la nota sobre la posición. | J29: Cumple | K29: 0.1.0 | L29: F1.1 #14 | M29: Pendiente | N29: Cliente
A30: D-07 | B30: Diapasón | C30: Marcadores de posición en los trastes habituales (3, 5, 7, 9, 12, 15, 17, 19, 21, 24). | D30: Media | E30: Cliente · listado 14/09 | F30: F1 | G30: F1.1 | H30: I | I30: Marcas simples en los trastes 3, 5, 7, 9, 15, 17, 19 y 21, y dobles en 12 y 24. | J30: Cumple | K30: 0.1.0 | L30: F1.1 #14 | M30: Pendiente | N30: Auditor de requisitos
A31: S-01 | B31: Sonido | C31: El sonido corresponde a una guitarra real, no a un sintetizador genérico. | D31: Alta | E31: Cliente · listado 14/09 | F31: F1 · F2 | G31: F1.1 · F2.2 · F2.4 | H31: D | I31: Con conexión suenan las muestras, no el sintetizador; en la pestaña Red se ven descargadas. | J31: Cumple | K31: 0.1.0 | L31: F1.1 #14 | M31: Pendiente | N31: Cliente | O31: Hoy con Tone.js y samples de un tercero. En F2 se sustituye por un reproductor propio con samples alojados en el proyecto (S-07).
A32: S-02 | B32: Sonido | C32: El usuario elige entre guitarra clásica (nylon) y acústica (acero). | D32: Alta | E32: Cliente · listado 14/09 | F32: F1 | G32: F1.1 | H32: D | I32: Elegir Acústica cambia el timbre audible y elegir Clásica lo devuelve. | J32: Cumple | K32: 0.1.0 | L32: F1.1 #5 | M32: Pendiente | N32: Cliente | O32: Cambiar de timbre descarga otro set de muestras, con aviso. Desde 0.1.2, dos cambios seguidos ya no muestran el mensaje de la carga descartada.
A33: S-03 | B33: Sonido | C33: La selección de timbre está en el menú de configuración. | D33: Alta | E33: Cliente · listado 14/09 | F33: F1 | G33: F1.1 | H33: I | I33: El selector de timbre está en Ajustes. | J33: Cumple | K33: 0.1.0 | L33: F1.1 #14 | M33: Pendiente | N33: Auditor de requisitos
A34: S-04 | B34: Sonido | C34: Si los samples no cargan, la app sigue sonando por síntesis. | D34: Media | E34: Cliente · listado 14/09 | F34: F1 | G34: F1.1 | H34: T | I34: Sin conexión, la app suena con el sintetizador y lo avisa en la pantalla de entrada. | J34: Cumple | K34: 0.1.0 | L34: — | M34: Pendiente | N34: Banco automático + auditor técnico | O34: Karplus-Strong con filtros que imitan la caja de resonancia. Desde 0.1.1 cada nota se calcula una sola vez y se reutiliza.
A35: S-05 | B35: Sonido | C35: El primer sonido requiere una interacción explícita del usuario. | D35: Alta | E35: Cliente · listado 14/09 | F35: F1 | G35: F1.1 | H35: D | I35: No suena nada antes de pulsar «Empezar». | J35: Cumple | K35: 0.1.0 | L35: F1.1 #14 | M35: Pendiente | N35: Cliente | O35: Lo impone la política de reproducción automática de los navegadores.
A36: S-06 | B36: Sonido | C36: El timbre persiste entre sesiones. | D36: Media | E36: Cliente · listado 14/09 | F36: F1 | G36: F1.1 | H36: D | I36: Tras recargar se mantiene el timbre elegido. | J36: Cumple | K36: 0.1.0 | L36: F1.1 #13 | M36: Pendiente | N36: Cliente
A37: S-07 | B37: Sonido | C37: Los samples de audio se alojan en el propio proyecto, con licencia verificada y documentada. | D37: Alta | E37: AR-01 | F37: F2 | G37: F2.1 · F2.3 | H37: I | I37: Ninguna petición de audio sale del dominio propio, y CREDITOS.md documenta origen y licencia. | J37: No cumple | K37: — | L37: — | M37: Pendiente | N37: Auditor de requisitos | O37: Antes asignado a V1; pasa a F2, la fase del sonido. Opciones y análisis en la sección de riesgos. | Q37: Modificado
A38: P-01 | B38: Pentagrama | C38: Al pulsar una nota en el mástil, se representa en el pentagrama. | D38: Alta | E38: Cliente · listado 14/09 | F38: F1 | G38: F1.1 | H38: A | I38: Toda posición del mástil, en cualquier afinación permitida, se dibuja dentro del pentagrama. | J38: Cumple | K38: 0.1.0 | L38: Análisis 15/09: ninguna nota fuera en todo el rango · F1.1 #3 y #4 | M38: Verificado parcialmente | N38: Auditor técnico | O38: Clave de sol octavada. Desde 0.1.1 las notas muy agudas o graves se dibujan transportadas con 8va, 15ma u 8vb, y la clave es un trazado propio que no depende de las fuentes del sistema.
A39: P-02 | B39: Pentagrama | C39: El pentagrama se puede mostrar u ocultar. | D39: Alta | E39: Cliente · listado 14/09 | F39: F1 | G39: F1.1 | H39: D | I39: El pentagrama se oculta y se muestra desde el chip y desde Ajustes. | J39: Cumple | K39: 0.1.0 | L39: F1.1 #14 | M39: Pendiente | N39: Cliente | O39: En configuración y en acceso rápido.
A40: P-03 | B40: Pentagrama | C40: El pentagrama está disponible en todos los modos de aprendizaje. | D40: Media | E40: Cliente · listado 14/09 | F40: F5 | G40: F5.3 | H40: D | I40: El pentagrama funciona en Libre, Adivinar y Escalas. | J40: Cumple parcialmente | K40: 0.1.0 | L40: — | M40: Pendiente | N40: Cliente | O40: Libre y Adivinar sí. Escalas, en F5.
A41: P-04 | B41: Pentagrama | C41: En el afinador, la afinación seleccionada se muestra como seis notas en un pentagrama. | D41: Media | E41: Cliente · listado 14/09 | F41: F1 | G41: F1.1 | H41: D | I41: El afinador muestra en un pentagrama las seis notas de la afinación activa. | J41: Cumple | K41: 0.1.0 | L41: F1.1 #14 | M41: Pendiente | N41: Cliente
...

Sheet Resumen
A1: Resumen de cumplimiento
A2: Todas las cifras son fórmulas sobre la hoja Matriz: cambian solas al actualizar una declaración o un estado. Un requisito asignado a dos fases cuenta en las dos; el total cuenta cada requisito una vez.
A4: Fase | B4: Requisitos | C4: Cumple | D4: Cumple parcialmente | E4: No cumple | F4: No aplica | G4: % que cumple | H4: Verificados | I4: Verificados parcialmente
A5: F1 · Base local verificada | B5: =COUNTIF(Matriz!$F$5:$F$94,"*F1*") -> 59 | C5: =COUNTIFS(Matriz!$F$5:$F$94,"*F1*",Matriz!$J$5:$J$94,"Cumple") -> 58 | D5: =COUNTIFS(Matriz!$F$5:$F$94,"*F1*",Matriz!$J$5:$J$94,"Cumple parcialmente") -> 1 | E5: =COUNTIFS(Matriz!$F$5:$F$94,"*F1*",Matriz!$J$5:$J$94,"No cumple") -> 0 | F5: =COUNTIFS(Matriz!$F$5:$F$94,"*F1*",Matriz!$J$5:$J$94,"No aplica") -> 0 | G5: =IFERROR(C5/B5,0) -> 0.98305085 | H5: =COUNTIFS(Matriz!$F$5:$F$94,"*F1*",Matriz!$M$5:$M$94,"Verificado") -> 0 | I5: =COUNTIFS(Matriz!$F$5:$F$94,"*F1*",Matriz!$M$5:$M$94,"Verificado parcialmente") -> 13
A6: F2 · Sonido propio y archivo autónomo | B6: =COUNTIF(Matriz!$F$5:$F$94,"*F2*") -> 7 | C6: =COUNTIFS(Matriz!$F$5:$F$94,"*F2*",Matriz!$J$5:$J$94,"Cumple") -> 1 | D6: =COUNTIFS(Matriz!$F$5:$F$94,"*F2*",Matriz!$J$5:$J$94,"Cumple parcialmente") -> 4 | E6: =COUNTIFS(Matriz!$F$5:$F$94,"*F2*",Matriz!$J$5:$J$94,"No cumple") -> 2 | F6: =COUNTIFS(Matriz!$F$5:$F$94,"*F2*",Matriz!$J$5:$J$94,"No aplica") -> 0 | G6: =IFERROR(C6/B6,0) -> 0.14285714 | H6: =COUNTIFS(Matriz!$F$5:$F$94,"*F2*",Matriz!$M$5:$M$94,"Verificado") -> 0 | I6: =COUNTIFS(Matriz!$F$5:$F$94,"*F2*",Matriz!$M$5:$M$94,"Verificado parcialmente") -> 0
A7: F3 · Interfaz y adaptación | B7: =COUNTIF(Matriz!$F$5:$F$94,"*F3*") -> 3 | C7: =COUNTIFS(Matriz!$F$5:$F$94,"*F3*",Matriz!$J$5:$J$94,"Cumple") -> 0 | D7: =COUNTIFS(Matriz!$F$5:$F$94,"*F3*",Matriz!$J$5:$J$94,"Cumple parcialmente") -> 2 | E7: =COUNTIFS(Matriz!$F$5:$F$94,"*F3*",Matriz!$J$5:$J$94,"No cumple") -> 1 | F7: =COUNTIFS(Matriz!$F$5:$F$94,"*F3*",Matriz!$J$5:$J$94,"No aplica") -> 0 | G7: =IFERROR(C7/B7,0) -> 0 | H7: =COUNTIFS(Matriz!$F$5:$F$94,"*F3*",Matriz!$M$5:$M$94,"Verificado") -> 0 | I7: =COUNTIFS(Matriz!$F$5:$F$94,"*F3*",Matriz!$M$5:$M$94,"Verificado parcialmente") -> 0
A8: F4 · Afinador por micrófono | B8: =COUNTIF(Matriz!$F$5:$F$94,"*F4*") -> 7 | C8: =COUNTIFS(Matriz!$F$5:$F$94,"*F4*",Matriz!$J$5:$J$94,"Cumple") -> 0 | D8: =COUNTIFS(Matriz!$F$5:$F$94,"*F4*",Matriz!$J$5:$J$94,"Cumple parcialmente") -> 1 | E8: =COUNTIFS(Matriz!$F$5:$F$94,"*F4*",Matriz!$J$5:$J$94,"No cumple") -> 6 | F8: =COUNTIFS(Matriz!$F$5:$F$94,"*F4*",Matriz!$J$5:$J$94,"No aplica") -> 0 | G8: =IFERROR(C8/B8,0) -> 0 | H8: =COUNTIFS(Matriz!$F$5:$F$94,"*F4*",Matriz!$M$5:$M$94,"Verificado") -> 0 | I8: =COUNTIFS(Matriz!$F$5:$F$94,"*F4*",Matriz!$M$5:$M$94,"Verificado parcialmente") -> 0
A9: F5 · Escalas | B9: =COUNTIF(Matriz!$F$5:$F$94,"*F5*") -> 7 | C9: =COUNTIFS(Matriz!$F$5:$F$94,"*F5*",Matriz!$J$5:$J$94,"Cumple") -> 0 | D9: =COUNTIFS(Matriz!$F$5:$F$94,"*F5*",Matriz!$J$5:$J$94,"Cumple parcialmente") -> 1 | E9: =COUNTIFS(Matriz!$F$5:$F$94,"*F5*",Matriz!$J$5:$J$94,"No cumple") -> 6 | F9: =COUNTIFS(Matriz!$F$5:$F$94,"*F5*",Matriz!$J$5:$J$94,"No aplica") -> 0 | G9: =IFERROR(C9/B9,0) -> 0 | H9: =COUNTIFS(Matriz!$F$5:$F$94,"*F5*",Matriz!$M$5:$M$94,"Verificado") -> 0 | I9: =COUNTIFS(Matriz!$F$5:$F$94,"*F5*",Matriz!$M$5:$M$94,"Verificado parcialmente") -> 0
A10: F6 · Preparación para distribución | B10: =COUNTIF(Matriz!$F$5:$F$94,"*F6*") -> 5 | C10: =COUNTIFS(Matriz!$F$5:$F$94,"*F6*",Matriz!$J$5:$J$94,"Cumple") -> 0 | D10: =COUNTIFS(Matriz!$F$5:$F$94,"*F6*",Matriz!$J$5:$J$94,"Cumple parcialmente") -> 2 | E10: =COUNTIFS(Matriz!$F$5:$F$94,"*F6*",Matriz!$J$5:$J$94,"No cumple") -> 3 | F10: =COUNTIFS(Matriz!$F$5:$F$94,"*F6*",Matriz!$J$5:$J$94,"No aplica") -> 0 | G10: =IFERROR(C10/B10,0) -> 0 | H10: =COUNTIFS(Matriz!$F$5:$F$94,"*F6*",Matriz!$M$5:$M$94,"Verificado") -> 0 | I10: =COUNTIFS(Matriz!$F$5:$F$94,"*F6*",Matriz!$M$5:$M$94,"Verificado parcialmente") -> 0
A11: F7 · Publicación y lanzamiento | B11: =COUNTIF(Matriz!$F$5:$F$94,"*F7*") -> 7 | C11: =COUNTIFS(Matriz!$F$5:$F$94,"*F7*",Matriz!$J$5:$J$94,"Cumple") -> 0 | D11: =COUNTIFS(Matriz!$F$5:$F$94,"*F7*",Matriz!$J$5:$J$94,"Cumple parcialmente") -> 4 | E11: =COUNTIFS(Matriz!$F$5:$F$94,"*F7*",Matriz!$J$5:$J$94,"No cumple") -> 3 | F11: =COUNTIFS(Matriz!$F$5:$F$94,"*F7*",Matriz!$J$5:$J$94,"No aplica") -> 0 | G11: =IFERROR(C11/B11,0) -> 0 | H11: =COUNTIFS(Matriz!$F$5:$F$94,"*F7*",Matriz!$M$5:$M$94,"Verificado") -> 0 | I11: =COUNTIFS(Matriz!$F$5:$F$94,"*F7*",Matriz!$M$5:$M$94,"Verificado parcialmente") -> 0
A12: Posterior · fuera de alcance | B12: =COUNTIF(Matriz!$F$5:$F$94,"*Posterior*") -> 2 | C12: =COUNTIFS(Matriz!$F$5:$F$94,"*Posterior*",Matriz!$J$5:$J$94,"Cumple") -> 0 | D12: =COUNTIFS(Matriz!$F$5:$F$94,"*Posterior*",Matriz!$J$5:$J$94,"Cumple parcialmente") -> 0 | E12: =COUNTIFS(Matriz!$F$5:$F$94,"*Posterior*",Matriz!$J$5:$J$94,"No cumple") -> 0 | F12: =COUNTIFS(Matriz!$F$5:$F$94,"*Posterior*",Matriz!$J$5:$J$94,"No aplica") -> 2 | G12: =IFERROR(C12/B12,0) -> 0 | H12: =COUNTIFS(Matriz!$F$5:$F$94,"*Posterior*",Matriz!$M$5:$M$94,"Verificado") -> 0 | I12: =COUNTIFS(Matriz!$F$5:$F$94,"*Posterior*",Matriz!$M$5:$M$94,"Verificado parcialmente") -> 0
A13: Total del producto | B13: =COUNTA(Matriz!$A$5:$A$94) -> 90 | C13: =COUNTIF(Matriz!$J$5:$J$94,"Cumple") -> 58 | D13: =COUNTIF(Matriz!$J$5:$J$94,"Cumple parcialmente") -> 10 | E13: =COUNTIF(Matriz!$J$5:$J$94,"No cumple") -> 20 | F13: =COUNTIF(Matriz!$J$5:$J$94,"No aplica") -> 2 | G13: =IFERROR(C13/B13,0) -> 0.64444444 | H13: =COUNTIF(Matriz!$M$5:$M$94,"Verificado") -> 0 | I13: =COUNTIF(Matriz!$M$5:$M$94,"Verificado parcialmente") -> 13
A15: Por método de verificación
A16: I · Inspección | B16: =COUNTIF(Matriz!$H$5:$H$94,"I") -> 16
A17: A · Análisis | B17: =COUNTIF(Matriz!$H$5:$H$94,"A") -> 1
A18: D · Demostración | B18: =COUNTIF(Matriz!$H$5:$H$94,"D") -> 53
A19: T · Prueba | B19: =COUNTIF(Matriz!$H$5:$H$94,"T") -> 17
A20: I+T · Inspección y prueba | B20: =COUNTIF(Matriz!$H$5:$H$94,"I+T") -> 1
A21: N/A · No aplica | B21: =COUNTIF(Matriz!$H$5:$H$94,"N/A") -> 2

Sheet Leyenda
A1: Qué es | B1: Matriz de cumplimiento de requisitos entre el cliente, que define qué debe hacer el producto, y el proveedor, que lo construye y declara su grado de cumplimiento. Los auditores verifican de forma independiente. Equivale a una matriz de verificación cruzada (VCRM) de ingeniería de sistemas.
A2: Roles | B2: Cliente: Pablo Díaz Guerra. Proveedor: chat de Desarrollo, o el agente desarrollador en el modo acelerado. Verificación independiente: auditor de requisitos y auditor técnico.
A3: Qué celdas editas tú | B3: La columna «Comentario del cliente», en amarillo. Las declaraciones y los estados los actualiza el proveedor en cada entrega; tú los aceptas o los discutes en tu comentario.
A4: Ejemplo de comentario del cliente | B4: Aceptado en Chrome. Repetir en Firefox antes de marcarlo como verificado.
A5: Método · I | B5: Inspección: se comprueba mirando el producto, el código o la documentación, sin ejecutar nada especial.
A6: Método · A | B6: Análisis: se comprueba con un cálculo o un razonamiento sobre todos los casos, por ejemplo el rango completo del pentagrama.
A7: Método · D | B7: Demostración: se usa la app y se observa que hace lo pedido.
A8: Método · T | B8: Prueba: se mide con un procedimiento repetible y un resultado esperado, normalmente el banco de pruebas automático.
A9: Declaración del proveedor | B9: Cumple · Cumple parcialmente · No cumple (aún no implementado, planificado en su etapa) · No aplica (fuera de alcance).
A10: Estado de verificación | B10: Verificado: superó su criterio de aceptación con el método indicado. Verificado parcialmente: hay evidencia, pero falta parte del método, por ejemplo la demostración en un navegador real. Pendiente: sin evidencia todavía.
A11: Evidencia | B11: «Banco 0.1.2 (DOM simulado)» son las 28 pruebas automáticas ejecutadas sin navegador. «F1.1 #n» es la comprobación número n de la etapa F1.1 del roadmap.
A12: Regla de cierre | B12: Una etapa del roadmap se cierra cuando todos sus requisitos están en «Cumple» y «Verificado». En el modo acelerado esta regla es el criterio de parada de cada iteración automática.

Sheet Control de cambios
A1: Versión | B1: Fecha | C1: Requisitos | D1: App | E1: Cambios
A2: 1.0 | B2: 14/10/2026 | C2: v1.2 | D2: 0.1.2 | E2: Primera emisión. 90 requisitos con origen, método de verificación, criterio de aceptación, declaración del proveedor, evidencia y estado de verificación.
